<?xml version="1.0" ?>
<robot xmlns:xacro="http://www.ros.org/wiki/xacro">

    <xacro:include filename="$(find pr2_description)/urdf/gripper_v1/gripper.gazebo.xacro" />
    <xacro:include filename="$(find pr2_description)/urdf/gripper_v1/gripper.transmission.xacro" />

    <xacro:property name="gripper_mass"  value= "0.1" />
    <xacro:property name="finger_mass" value="0.1" />
    <xacro:property name="gripper_size"  value= "0.05" />

    <!--Gripper MACRO-->
    <xacro:macro name="pr2_gripper_v1" params="side parent">
        <link name="${side}_gripper_link">
            <inertial>
            <origin xyz="0 0 0" rpy="0 0 0"/>
            <mass value="${gripper_mass}"/>
            <inertia ixx="0.002" ixy="0" ixz="0" iyy="0.0002" iyz="0" izz="0.0002"/>
            </inertial>
            <visual>
            <origin xyz="0 0 0" rpy="0 0 0"/>
            <geometry>
                <mesh filename="package://pr2_description/meshes/gripper_v1/gripper_base.dae"/>
            </geometry>
            <material name="Grey2" />
            </visual>
            <collision>
            <origin xyz="0 0 0" rpy="0 0 0"/>
            <geometry>
                <mesh filename="package://pr2_description/meshes/gripper_v1/gripper_base.dae"/>
            </geometry>
            </collision>
        </link>
        <link name="${side}_right_gripper_finger_link">
            <inertial>
            <origin xyz="0 0 0" rpy="0 0 0"/>
            <mass value="${finger_mass}"/>
            <inertia ixx="0.002" ixy="0" ixz="0" iyy="0.0002" iyz="0" izz="0.0002"/>
            </inertial>
            <visual>
            <origin xyz="0 0 0" rpy="0 0 0"/>
            <geometry>
                <!-- <mesh filename="package://pr2_description/meshes/gripper/finger_right.dae"/> -->
                <mesh filename="package://pr2_description/meshes/gripper_v1/gripper_right_hook.dae"/>
            </geometry>
            <!-- <material name="Grey2" /> -->
            </visual>
            <collision>
            <origin xyz="0 0 0" rpy="0 0 0"/>
            <geometry>
                <!-- <mesh filename="package://pr2_description/meshes/gripper/finger_right_collision.dae"/> -->
                <mesh filename="package://pr2_description/meshes/gripper_v1/gripper_right_hook.dae"/>
            </geometry>
            </collision>
        </link>
        <link name="${side}_left_gripper_finger_link">
            <inertial>
            <origin xyz="0 0 0" rpy="0 0 0"/>
            <mass value="${finger_mass}"/>
            <inertia ixx="0.002" ixy="0" ixz="0" iyy="0.0002" iyz="0" izz="0.0002"/>
            </inertial>
            <visual>
            <origin xyz="0 0 0" rpy="0 0 0"/>
            <geometry>
                <!-- <mesh filename="package://pr2_description/meshes/gripper/finger_left.dae"/> -->
                <mesh filename="package://pr2_description/meshes/gripper_v1/gripper_left_hook.dae"/>
            </geometry>
            <!-- <material name="Grey2" /> -->
            </visual>
            <collision>
            <origin xyz="0 0 0" rpy="0 0 0"/>
            <geometry>
                <!-- <mesh filename="package://pr2_description/meshes/gripper/finger_left_collision.dae"/> -->
                <mesh filename="package://pr2_description/meshes/gripper_v1/gripper_left_hook.dae"/>
            </geometry>
            </collision>
        </link>

        <joint name="${side}_right_gripper_finger_joint" type="prismatic">
            <origin rpy="0 0 0" xyz="0.075 -0.06 0" />
            <parent link="${side}_gripper_link" />
            <child link="${side}_right_gripper_finger_link" />
            <axis xyz="0 1 0" />
            <limit effort="1000" lower="0.0" upper="0.05" velocity="0.05" />
            <dynamics damping="0.7" />
        </joint>
        <joint name="${side}_left_gripper_finger_joint" type="prismatic">
            <origin rpy="0 0 0" xyz="0.075 0.06 0" />
            <parent link="${side}_gripper_link" />
            <child link="${side}_left_gripper_finger_link" />
            <axis xyz="0 -1 0" />
            <limit effort="1000" lower="0.0" upper="0.05" velocity="0.05" />
            <dynamics damping="0.7" />
        </joint>
        <joint name="${side}_gripper_joint" type="fixed">
            <parent link="${parent}"/>
            <child link="${side}_gripper_link"/>
            <origin xyz="0.075 0 0" rpy="0 0 0"/><!--0.087-->
            <axis xyz="0 1 0" />
        </joint>

        <xacro:pr2_gripper_gazebo side="${side}"/>
        <xacro:pr2_gripper_transmission_v1 side="${side}"/>
        
    </xacro:macro>



</robot>